Workbook

Sheet README
A1: TruNorth Scoring Calculator (Build 54)
A3: Last updated: 2026-06-09 (post Build 54)
A4: Source of truth: src/App.jsx lines 623–810 (scoreCat + computeScore) and scripts/rebake-scoring.mjs (non-personalized baseScoreCat)
A6: HOW TO USE
A7: Open the 'Calculator' sheet. Yellow cells (blue text) are inputs you can edit. Light-blue cells (black text) are formulas — they recompute live.
A8: Three preset rows: Wendy's, Patagonia, and a Custom row. Override any input in the Custom row to model a hypothetical brand and watch the grade respond.
A10: SHEETS
A11: • Calculator — the interactive model
A12: • scoreCat — per-category enum→score lookup (used by Calculator's VLOOKUPs)
A13: • Weights — base weights + boost multipliers
A14: • Dealbreakers — penalty rules + worked example
A15: • Grade Thresholds — A/B/C/D/F bands
... A27: • Personalization adjusts scores per category based on user quiz: a Democrat user sees right-donating brands at 8 (very low) for political, left-donating at 97 (very high).

Sheet Calculator
A1: Brand | B1: Category enum values (INPUT — edit yellow cells) | L1: Quiz weights 1–3 (INPUT) | V1: User lean (INPUT) | AA1: Brand flags (INPUT) | AD1: Per-category score (FORMULA) | AN1: Effective weight (FORMULA) | AX1: Contribution = score × weight (FORMULA) | BH1: Result | BI1: Result | BJ1: Result | BK1: Result | BL1: Result | BM1: Result
B2: political | C2: charity | D2: environment | E2: labor | F2: dei | G2: animals | H2: guns | I2: privacy | J2: execPay | K2: health | L2: w_political | M2: w_charity | N2: w_environment | O2: w_labor | P2: w_dei | Q2: w_animals | R2: w_guns | S2: w_privacy | T2: w_execPay | U2: w_health | V2: lean (political) | W2: deiLean | X2: animalTesting | Y2: guns pref | Z2: unionSupport | AA2: foreignOwned | AB2: antitrust | AC2: childLabor | AD2: sc_political | AE2: sc_charity | AF2: sc_environment | AG2: sc_labor | AH2: sc_dei | AI2: sc_animals | AJ2: sc_guns | AK2: sc_privacy | AL2: sc_execPay | AM2: sc_health | AN2: ew_political | AO2: ew_charity | AP2: ew_environment | AQ2: ew_labor | AR2: ew_dei | AS2: ew_animals | AT2: ew_guns | AU2: ew_privacy | AV2: ew_execPay | AW2: ew_health | AX2: c_political | AY2: c_charity | AZ2: c_environment | BA2: c_labor | BB2: c_dei | BC2: c_animals | BD2: c_guns | BE2: c_privacy | BF2: c_execPay | BG2: c_health | BH2: Σ weight | BI2: Σ contrib | BJ2: Pre-penalty | BK2: Penalty | BL2: Final | BM2: Grade
A3: Wendy's (preset) | B3: right | C3: mixed | D3: neutral | E3: mixed | F3: neutral | G3: na | H3: neutral | I3: neutral | J3: na | K3: neutral | L3: 3 | M3: 2 | N3: 3 | O3: 3 | P3: 3 | Q3: 2 | R3: 2 | S3: 2 | T3: 2 | U3: 2 | V3: left | W3: pro | X3: prefer_not | Y3: avoid | Z3: pro | AA3: FALSE | AB3: FALSE | AC3: FALSE | AD3: =IFERROR(INDEX(scoreCat!$D$2:$D$99,MATCH("political|"&B3&"|"&V3,scoreCat!$F$2:$F$99,0)),50) | AE3: =IFERROR(INDEX(scoreCat!$D$2:$D$99,MATCH("charity|"&C3&"|any",scoreCat!$F$2:$F$99,0)),50) | AF3: =IFERROR(INDEX(scoreCat!$D$2:$D$99,MATCH("environment|"&D3&"|any",scoreCat!$F$2:$F$99,0)),50) | AG3: =IFERROR(INDEX(scoreCat!$D$2:$D$99,MATCH("labor|"&E3&"|"&Z3,scoreCat!$F$2:$F$99,0)),50) | AH3: =IFERROR(INDEX(scoreCat!$D$2:$D$99,MATCH("dei|"&F3&"|"&W3,scoreCat!$F$2:$F$99,0)),50) | AI3: =IFERROR(INDEX(scoreCat!$D$2:$D$99,MATCH("animals|"&G3&"|"&X3,scoreCat!$F$2:$F$99,0)),50) | AJ3: =IFERROR(INDEX(scoreCat!$D$2:$D$99,MATCH("guns|"&H3&"|"&Y3,scoreCat!$F$2:$F$99,0)),50) | AK3: =IFERROR(INDEX(scoreCat!$D$2:$D$99,MATCH("privacy|"&I3&"|any",scoreCat!$F$2:$F$99,0)),50) | AL3: =IFERROR(INDEX(scoreCat!$D$2:$D$99,MATCH("execPay|"&J3&"|any",scoreCat!$F$2:$F$99,0)),50) | AM3: =IFERROR(INDEX(scoreCat!$D$2:$D$99,MATCH("health|"&K3&"|any",scoreCat!$F$2:$F$99,0)),50) | AN3: =L3*IF(AND(V3<>"neutral",V3<>""),2,1) | AO3: =M3*1 | AP3: =N3*1 | AQ3: =O3*IF(AND(Z3<>"neutral",Z3<>""),2,1) | AR3: =P3*IF(AND(W3<>"neutral",W3<>""),2,1) | AS3: =Q3*IF(AND(X3<>"neutral",X3<>""),2,1) | AT3: =R3*IF(AND(Y3<>"neutral",Y3<>""),4,1) | AU3: =S3*1 | AV3: =T3*1 | AW3: =U3*1 | AX3: =IF(OR(B3="neutral",B3="na",B3="n/a",B3=""),0,AD3*AN3) | AY3: =IF(OR(C3="neutral",C3="na",C3="n/a",C3=""),0,AE3*AO3) | AZ3: =IF(OR(D3="neutral",D3="na",D3="n/a",D3=""),0,AF3*AP3) | BA3: =IF(OR(E3="neutral",E3="na",E3="n/a",E3=""),0,AG3*AQ3) | BB3: =IF(OR(F3="neutral",F3="na",F3="n/a",F3=""),0,AH3*AR3) | BC3: =IF(OR(G3="neutral",G3="na",G3="n/a",G3=""),0,AI3*AS3) | BD3: =IF(OR(H3="neutral",H3="na",H3="n/a",H3=""),0,AJ3*AT3) | BE3: =IF(OR(I3="neutral",I3="na",I3="n/a",I3=""),0,AK3*AU3) | ... BG3: =IF(OR(K3="neutral",K3="na",K3="n/a",K3=""),0,AM3*AW3) | BH3: =IF(OR(B3="neutral",B3="na",B3="n/a",B3=""),0,AN3)+IF(OR(C3="neutral",C3="na",C3="n/a",C3=""),0,AO3)+IF(OR(D3="neutral",D3="na",D3="n/a",D3=""),0,AP3)+IF(OR(E3="neutral",E3="na",E3="n/a",E3=""),0,AQ3)+IF(OR(F3="neutral",F3="na",F3="n/a",F3=""),0,AR3)+IF(OR(G3="neutral",G3="na",G3="n/a",G3=""),0,AS3)+IF(OR(H3="neutral",H3="na",H3="n/a",H3=""),0,AT3)+IF(OR(I3="neutral",I3="na",I3="n/a",I3=""),0,AU3)+IF(OR(J3="neutral",J3="na",J3="n/a",J3=""),0,AV3)+IF(OR(K3="neutral",K3="na",K3="n/a",K3=""),0,AW3) | BI3: =SUM(AX3:BG3) | BJ3: =IF(BH3=0,"?",BI3/BH3) | BK3: =IF(AA3=TRUE,30,0)+IF(AB3=TRUE,25,0)+IF(AC3=TRUE,30,0) | BL3: =IF(BJ3="?","?",MAX(0,MIN(100,ROUND(BJ3-BK3,0)))) | BM3: =IF(BL3="?","?",IF(BL3>=75,"A",IF(BL3>=62,"B",IF(BL3>=48,"C",IF(BL3>=35,"D","F")))))
A4: Patagonia (preset) | B4: neutral | C4: positive | D4: positive | E4: neutral | F4: neutral | G4: na | H4: neutral | I4: na | J4: na | K4: neutral | L4: 3 | M4: 2 | N4: 3 | O4: 3 | P4: 3 | Q4: 2 | R4: 2 | S4: 2 | T4: 2 | U4: 2 | V4: left | W4: pro | X4: prefer_not | Y4: avoid | Z4: pro | AA4: FALSE | AB4: FALSE | AC4: FALSE | AD4: =IFERROR(INDEX(scoreCat!$D$2:$D$99,MATCH("political|"&B4&"|"&V4,scoreCat!$F$2:$F$99,0)),50) | AE4: =IFERROR(INDEX(scoreCat!$D$2:$D$99,MATCH("charity|"&C4&"|any",scoreCat!$F$2:$F$99,0)),50) | AF4: =IFERROR(INDEX(scoreCat!$D$2:$D$99,MATCH("environment|"&D4&"|any",scoreCat!$F$2:$F$99,0)),50) | AG4: =IFERROR(INDEX(scoreCat!$D$2:$D$99,MATCH("labor|"&E4&"|"&Z4,scoreCat!$F$2:$F$99,0)),50) | AH4: =IFERROR(INDEX(scoreCat!$D$2:$D$99,MATCH("dei|"&F4&"|"&W4,scoreCat!$F$2:$F$99,0)),50) | AI4: =IFERROR(INDEX(scoreCat!$D$2:$D$99,MATCH("animals|"&G4&"|"&X4,scoreCat!$F$2:$F$99,0)),50) | AJ4: =IFERROR(INDEX(scoreCat!$D$2:$D$99,MATCH("guns|"&H4&"|"&Y4,scoreCat!$F$2:$F$99,0)),50) | AK4: =IFERROR(INDEX(scoreCat!$D$2:$D$99,MATCH("privacy|"&I4&"|any",scoreCat!$F$2:$F$99,0)),50) | AL4: =IFERROR(INDEX(scoreCat!$D$2:$D$99,MATCH("execPay|"&J4&"|any",scoreCat!$F$2:$F$99,0)),50) | AM4: =IFERROR(INDEX(scoreCat!$D$2:$D$99,MATCH("health|"&K4&"|any",scoreCat!$F$2:$F$99,0)),50) | AN4: =L4*IF(AND(V4<>"neutral",V4<>""),2,1) | AO4: =M4*1 | AP4: =N4*1 | AQ4: =O4*IF(AND(Z4<>"neutral",Z4<>""),2,1) | AR4: =P4*IF(AND(W4<>"neutral",W4<>""),2,1) | AS4: =Q4*IF(AND(X4<>"neutral",X4<>""),2,1) | AT4: =R4*IF(AND(Y4<>"neutral",Y4<>""),4,1) | AU4: =S4*1 | AV4: =T4*1 | AW4: =U4*1 | AX4: =IF(OR(B4="neutral",B4="na",B4="n/a",B4=""),0,AD4*AN4) | AY4: =IF(OR(C4="neutral",C4="na",C4="n/a",C4=""),0,AE4*AO4) | AZ4: =IF(OR(D4="neutral",D4="na",D4="n/a",D4=""),0,AF4*AP4) | BA4: =IF(OR(E4="neutral",E4="na",E4="n/a",E4=""),0,AG4*AQ4) | BB4: =IF(OR(F4="neutral",F4="na",F4="n/a",F4=""),0,AH4*AR4) | BC4: =IF(OR(G4="neutral",G4="na",G4="n/a",G4=""),0,AI4*AS4) | BD4: =IF(OR(H4="neutral",H4="na",H4="n/a",H4=""),0,AJ4*AT4) | BE4: =IF(OR(I4="neutral",I4="na",I4="n/a",I4=""),0,AK4*AU4) | ... BG4: =IF(OR(K4="neutral",K4="na",K4="n/a",K4=""),0,AM4*AW4) | BH4: =IF(OR(B4="neutral",B4="na",B4="n/a",B4=""),0,AN4)+IF(OR(C4="neutral",C4="na",C4="n/a",C4=""),0,AO4)+IF(OR(D4="neutral",D4="na",D4="n/a",D4=""),0,AP4)+IF(OR(E4="neutral",E4="na",E4="n/a",E4=""),0,AQ4)+IF(OR(F4="neutral",F4="na",F4="n/a",F4=""),0,AR4)+IF(OR(G4="neutral",G4="na",G4="n/a",G4=""),0,AS4)+IF(OR(H4="neutral",H4="na",H4="n/a",H4=""),0,AT4)+IF(OR(I4="neutral",I4="na",I4="n/a",I4=""),0,AU4)+IF(OR(J4="neutral",J4="na",J4="n/a",J4=""),0,AV4)+IF(OR(K4="neutral",K4="na",K4="n/a",K4=""),0,AW4) | BI4: =SUM(AX4:BG4) | BJ4: =IF(BH4=0,"?",BI4/BH4) | BK4: =IF(AA4=TRUE,30,0)+IF(AB4=TRUE,25,0)+IF(AC4=TRUE,30,0) | BL4: =IF(BJ4="?","?",MAX(0,MIN(100,ROUND(BJ4-BK4,0)))) | BM4: =IF(BL4="?","?",IF(BL4>=75,"A",IF(BL4>=62,"B",IF(BL4>=48,"C",IF(BL4>=35,"D","F")))))
A5: Nestlé (preset) | B5: bipartisan | C5: mixed | D5: neutral | E5: neutral | F5: neutral | G5: neutral | H5: neutral | I5: neutral | J5: na | K5: neutral | L5: 3 | M5: 2 | N5: 3 | O5: 3 | P5: 3 | Q5: 2 | R5: 2 | S5: 2 | T5: 2 | U5: 2 | V5: left | W5: pro | X5: prefer_not | Y5: avoid | Z5: pro | AA5: TRUE | AB5: FALSE | AC5: FALSE | AD5: =IFERROR(INDEX(scoreCat!$D$2:$D$99,MATCH("political|"&B5&"|"&V5,scoreCat!$F$2:$F$99,0)),50) | AE5: =IFERROR(INDEX(scoreCat!$D$2:$D$99,MATCH("charity|"&C5&"|any",scoreCat!$F$2:$F$99,0)),50) | AF5: =IFERROR(INDEX(scoreCat!$D$2:$D$99,MATCH("environment|"&D5&"|any",scoreCat!$F$2:$F$99,0)),50) | AG5: =IFERROR(INDEX(scoreCat!$D$2:$D$99,MATCH("labor|"&E5&"|"&Z5,scoreCat!$F$2:$F$99,0)),50) | AH5: =IFERROR(INDEX(scoreCat!$D$2:$D$99,MATCH("dei|"&F5&"|"&W5,scoreCat!$F$2:$F$99,0)),50) | AI5: =IFERROR(INDEX(scoreCat!$D$2:$D$99,MATCH("animals|"&G5&"|"&X5,scoreCat!$F$2:$F$99,0)),50) | AJ5: =IFERROR(INDEX(scoreCat!$D$2:$D$99,MATCH("guns|"&H5&"|"&Y5,scoreCat!$F$2:$F$99,0)),50) | AK5: =IFERROR(INDEX(scoreCat!$D$2:$D$99,MATCH("privacy|"&I5&"|any",scoreCat!$F$2:$F$99,0)),50) | AL5: =IFERROR(INDEX(scoreCat!$D$2:$D$99,MATCH("execPay|"&J5&"|any",scoreCat!$F$2:$F$99,0)),50) | AM5: =IFERROR(INDEX(scoreCat!$D$2:$D$99,MATCH("health|"&K5&"|any",scoreCat!$F$2:$F$99,0)),50) | AN5: =L5*IF(AND(V5<>"neutral",V5<>""),2,1) | AO5: =M5*1 | AP5: =N5*1 | AQ5: =O5*IF(AND(Z5<>"neutral",Z5<>""),2,1) | AR5: =P5*IF(AND(W5<>"neutral",W5<>""),2,1) | AS5: =Q5*IF(AND(X5<>"neutral",X5<>""),2,1) | AT5: =R5*IF(AND(Y5<>"neutral",Y5<>""),4,1) | AU5: =S5*1 | AV5: =T5*1 | AW5: =U5*1 | AX5: =IF(OR(B5="neutral",B5="na",B5="n/a",B5=""),0,AD5*AN5) | AY5: =IF(OR(C5="neutral",C5="na",C5="n/a",C5=""),0,AE5*AO5) | AZ5: =IF(OR(D5="neutral",D5="na",D5="n/a",D5=""),0,AF5*AP5) | BA5: =IF(OR(E5="neutral",E5="na",E5="n/a",E5=""),0,AG5*AQ5) | BB5: =IF(OR(F5="neutral",F5="na",F5="n/a",F5=""),0,AH5*AR5) | BC5: =IF(OR(G5="neutral",G5="na",G5="n/a",G5=""),0,AI5*AS5) | BD5: =IF(OR(H5="neutral",H5="na",H5="n/a",H5=""),0,AJ5*AT5) | BE5: =IF(OR(I5="neutral",I5="na",I5="n/a",I5=""),0,AK5*AU5) | ... BG5: =IF(OR(K5="neutral",K5="na",K5="n/a",K5=""),0,AM5*AW5) | BH5: =IF(OR(B5="neutral",B5="na",B5="n/a",B5=""),0,AN5)+IF(OR(C5="neutral",C5="na",C5="n/a",C5=""),0,AO5)+IF(OR(D5="neutral",D5="na",D5="n/a",D5=""),0,AP5)+IF(OR(E5="neutral",E5="na",E5="n/a",E5=""),0,AQ5)+IF(OR(F5="neutral",F5="na",F5="n/a",F5=""),0,AR5)+IF(OR(G5="neutral",G5="na",G5="n/a",G5=""),0,AS5)+IF(OR(H5="neutral",H5="na",H5="n/a",H5=""),0,AT5)+IF(OR(I5="neutral",I5="na",I5="n/a",I5=""),0,AU5)+IF(OR(J5="neutral",J5="na",J5="n/a",J5=""),0,AV5)+IF(OR(K5="neutral",K5="na",K5="n/a",K5=""),0,AW5) | BI5: =SUM(AX5:BG5) | BJ5: =IF(BH5=0,"?",BI5/BH5) | BK5: =IF(AA5=TRUE,30,0)+IF(AB5=TRUE,25,0)+IF(AC5=TRUE,30,0) | BL5: =IF(BJ5="?","?",MAX(0,MIN(100,ROUND(BJ5-BK5,0)))) | BM5: =IF(BL5="?","?",IF(BL5>=75,"A",IF(BL5>=62,"B",IF(BL5>=48,"C",IF(BL5>=35,"D","F")))))
A6: Custom (your sandbox) | B6: right | C6: neutral | D6: poor | E6: poor | F6: neutral | G6: na | H6: neutral | I6: neutral | J6: na | K6: neutral | L6: 3 | M6: 2 | N6: 3 | O6: 3 | P6: 3 | Q6: 2 | R6: 2 | S6: 2 | T6: 2 | U6: 2 | V6: left | W6: pro | X6: prefer_not | Y6: avoid | Z6: pro | AA6: FALSE | AB6: FALSE | AC6: FALSE | AD6: =IFERROR(INDEX(scoreCat!$D$2:$D$99,MATCH("political|"&B6&"|"&V6,scoreCat!$F$2:$F$99,0)),50) | AE6: =IFERROR(INDEX(scoreCat!$D$2:$D$99,MATCH("charity|"&C6&"|any",scoreCat!$F$2:$F$99,0)),50) | AF6: =IFERROR(INDEX(scoreCat!$D$2:$D$99,MATCH("environment|"&D6&"|any",scoreCat!$F$2:$F$99,0)),50) | AG6: =IFERROR(INDEX(scoreCat!$D$2:$D$99,MATCH("labor|"&E6&"|"&Z6,scoreCat!$F$2:$F$99,0)),50) | AH6: =IFERROR(INDEX(scoreCat!$D$2:$D$99,MATCH("dei|"&F6&"|"&W6,scoreCat!$F$2:$F$99,0)),50) | AI6: =IFERROR(INDEX(scoreCat!$D$2:$D$99,MATCH("animals|"&G6&"|"&X6,scoreCat!$F$2:$F$99,0)),50) | AJ6: =IFERROR(INDEX(scoreCat!$D$2:$D$99,MATCH("guns|"&H6&"|"&Y6,scoreCat!$F$2:$F$99,0)),50) | AK6: =IFERROR(INDEX(scoreCat!$D$2:$D$99,MATCH("privacy|"&I6&"|any",scoreCat!$F$2:$F$99,0)),50) | AL6: =IFERROR(INDEX(scoreCat!$D$2:$D$99,MATCH("execPay|"&J6&"|any",scoreCat!$F$2:$F$99,0)),50) | AM6: =IFERROR(INDEX(scoreCat!$D$2:$D$99,MATCH("health|"&K6&"|any",scoreCat!$F$2:$F$99,0)),50) | AN6: =L6*IF(AND(V6<>"neutral",V6<>""),2,1) | AO6: =M6*1 | AP6: =N6*1 | AQ6: =O6*IF(AND(Z6<>"neutral",Z6<>""),2,1) | AR6: =P6*IF(AND(W6<>"neutral",W6<>""),2,1) | AS6: =Q6*IF(AND(X6<>"neutral",X6<>""),2,1) | AT6: =R6*IF(AND(Y6<>"neutral",Y6<>""),4,1) | AU6: =S6*1 | AV6: =T6*1 | AW6: =U6*1 | AX6: =IF(OR(B6="neutral",B6="na",B6="n/a",B6=""),0,AD6*AN6) | AY6: =IF(OR(C6="neutral",C6="na",C6="n/a",C6=""),0,AE6*AO6) | AZ6: =IF(OR(D6="neutral",D6="na",D6="n/a",D6=""),0,AF6*AP6) | BA6: =IF(OR(E6="neutral",E6="na",E6="n/a",E6=""),0,AG6*AQ6) | BB6: =IF(OR(F6="neutral",F6="na",F6="n/a",F6=""),0,AH6*AR6) | BC6: =IF(OR(G6="neutral",G6="na",G6="n/a",G6=""),0,AI6*AS6) | BD6: =IF(OR(H6="neutral",H6="na",H6="n/a",H6=""),0,AJ6*AT6) | BE6: =IF(OR(I6="neutral",I6="na",I6="n/a",I6=""),0,AK6*AU6) | ... BG6: =IF(OR(K6="neutral",K6="na",K6="n/a",K6=""),0,AM6*AW6) | BH6: =IF(OR(B6="neutral",B6="na",B6="n/a",B6=""),0,AN6)+IF(OR(C6="neutral",C6="na",C6="n/a",C6=""),0,AO6)+IF(OR(D6="neutral",D6="na",D6="n/a",D6=""),0,AP6)+IF(OR(E6="neutral",E6="na",E6="n/a",E6=""),0,AQ6)+IF(OR(F6="neutral",F6="na",F6="n/a",F6=""),0,AR6)+IF(OR(G6="neutral",G6="na",G6="n/a",G6=""),0,AS6)+IF(OR(H6="neutral",H6="na",H6="n/a",H6=""),0,AT6)+IF(OR(I6="neutral",I6="na",I6="n/a",I6=""),0,AU6)+IF(OR(J6="neutral",J6="na",J6="n/a",J6=""),0,AV6)+IF(OR(K6="neutral",K6="na",K6="n/a",K6=""),0,AW6) | BI6: =SUM(AX6:BG6) | BJ6: =IF(BH6=0,"?",BI6/BH6) | BK6: =IF(AA6=TRUE,30,0)+IF(AB6=TRUE,25,0)+IF(AC6=TRUE,30,0) | BL6: =IF(BJ6="?","?",MAX(0,MIN(100,ROUND(BJ6-BK6,0)))) | BM6: =IF(BL6="?","?",IF(BL6>=75,"A",IF(BL6>=62,"B",IF(BL6>=48,"C",IF(BL6>=35,"D","F")))))
A7: (empty row 1) | B7: neutral | C7: neutral | D7: neutral | E7: neutral | F7: neutral | G7: neutral | H7: neutral | I7: neutral | J7: neutral | K7: neutral | L7: 3 | M7: 2 | N7: 3 | O7: 3 | P7: 3 | Q7: 2 | R7: 2 | S7: 2 | T7: 2 | U7: 2 | V7: neutral | W7: neutral | X7: neutral | Y7: neutral | Z7: neutral | AA7: FALSE | AB7: FALSE | AC7: FALSE | AD7: =IFERROR(INDEX(scoreCat!$D$2:$D$99,MATCH("political|"&B7&"|"&V7,scoreCat!$F$2:$F$99,0)),50) | AE7: =IFERROR(INDEX(scoreCat!$D$2:$D$99,MATCH("charity|"&C7&"|any",scoreCat!$F$2:$F$99,0)),50) | AF7: =IFERROR(INDEX(scoreCat!$D$2:$D$99,MATCH("environment|"&D7&"|any",scoreCat!$F$2:$F$99,0)),50) | AG7: =IFERROR(INDEX(scoreCat!$D$2:$D$99,MATCH("labor|"&E7&"|"&Z7,scoreCat!$F$2:$F$99,0)),50) | AH7: =IFERROR(INDEX(scoreCat!$D$2:$D$99,MATCH("dei|"&F7&"|"&W7,scoreCat!$F$2:$F$99,0)),50) | AI7: =IFERROR(INDEX(scoreCat!$D$2:$D$99,MATCH("animals|"&G7&"|"&X7,scoreCat!$F$2:$F$99,0)),50) | AJ7: =IFERROR(INDEX(scoreCat!$D$2:$D$99,MATCH("guns|"&H7&"|"&Y7,scoreCat!$F$2:$F$99,0)),50) | AK7: =IFERROR(INDEX(scoreCat!$D$2:$D$99,MATCH("privacy|"&I7&"|any",scoreCat!$F$2:$F$99,0)),50) | AL7: =IFERROR(INDEX(scoreCat!$D$2:$D$99,MATCH("execPay|"&J7&"|any",scoreCat!$F$2:$F$99,0)),50) | AM7: =IFERROR(INDEX(scoreCat!$D$2:$D$99,MATCH("health|"&K7&"|any",scoreCat!$F$2:$F$99,0)),50) | AN7: =L7*IF(AND(V7<>"neutral",V7<>""),2,1) | AO7: =M7*1 | AP7: =N7*1 | AQ7: =O7*IF(AND(Z7<>"neutral",Z7<>""),2,1) | AR7: =P7*IF(AND(W7<>"neutral",W7<>""),2,1) | AS7: =Q7*IF(AND(X7<>"neutral",X7<>""),2,1) | AT7: =R7*IF(AND(Y7<>"neutral",Y7<>""),4,1) | AU7: =S7*1 | AV7: =T7*1 | AW7: =U7*1 | AX7: =IF(OR(B7="neutral",B7="na",B7="n/a",B7=""),0,AD7*AN7) | AY7: =IF(OR(C7="neutral",C7="na",C7="n/a",C7=""),0,AE7*AO7) | AZ7: =IF(OR(D7="neutral",D7="na",D7="n/a",D7=""),0,AF7*AP7) | BA7: =IF(OR(E7="neutral",E7="na",E7="n/a",E7=""),0,AG7*AQ7) | BB7: =IF(OR(F7="neutral",F7="na",F7="n/a",F7=""),0,AH7*AR7) | BC7: =IF(OR(G7="neutral",G7="na",G7="n/a",G7=""),0,AI7*AS7) | BD7: =IF(OR(H7="neutral",H7="na",H7="n/a",H7=""),0,AJ7*AT7) | BE7: =IF(OR(I7="neutral",I7="na",I7="n/a",I7=""),0,AK7*AU7) | ... BG7: =IF(OR(K7="neutral",K7="na",K7="n/a",K7=""),0,AM7*AW7) | BH7: =IF(OR(B7="neutral",B7="na",B7="n/a",B7=""),0,AN7)+IF(OR(C7="neutral",C7="na",C7="n/a",C7=""),0,AO7)+IF(OR(D7="neutral",D7="na",D7="n/a",D7=""),0,AP7)+IF(OR(E7="neutral",E7="na",E7="n/a",E7=""),0,AQ7)+IF(OR(F7="neutral",F7="na",F7="n/a",F7=""),0,AR7)+IF(OR(G7="neutral",G7="na",G7="n/a",G7=""),0,AS7)+IF(OR(H7="neutral",H7="na",H7="n/a",H7=""),0,AT7)+IF(OR(I7="neutral",I7="na",I7="n/a",I7=""),0,AU7)+IF(OR(J7="neutral",J7="na",J7="n/a",J7=""),0,AV7)+IF(OR(K7="neutral",K7="na",K7="n/a",K7=""),0,AW7) | BI7: =SUM(AX7:BG7) | BJ7: =IF(BH7=0,"?",BI7/BH7) | BK7: =IF(AA7=TRUE,30,0)+IF(AB7=TRUE,25,0)+IF(AC7=TRUE,30,0) | BL7: =IF(BJ7="?","?",MAX(0,MIN(100,ROUND(BJ7-BK7,0)))) | BM7: =IF(BL7="?","?",IF(BL7>=75,"A",IF(BL7>=62,"B",IF(BL7>=48,"C",IF(BL7>=35,"D","F")))))
A8: (empty row 2) | B8: neutral | C8: neutral | D8: neutral | E8: neutral | F8: neutral | G8: neutral | H8: neutral | I8: neutral | J8: neutral | K8: neutral | L8: 3 | M8: 2 | N8: 3 | O8: 3 | P8: 3 | Q8: 2 | R8: 2 | S8: 2 | T8: 2 | U8: 2 | V8: neutral | W8: neutral | X8: neutral | Y8: neutral | Z8: neutral | AA8: FALSE | AB8: FALSE | AC8: FALSE | AD8: =IFERROR(INDEX(scoreCat!$D$2:$D$99,MATCH("political|"&B8&"|"&V8,scoreCat!$F$2:$F$99,0)),50) | AE8: =IFERROR(INDEX(scoreCat!$D$2:$D$99,MATCH("charity|"&C8&"|any",scoreCat!$F$2:$F$99,0)),50) | AF8: =IFERROR(INDEX(scoreCat!$D$2:$D$99,MATCH("environment|"&D8&"|any",scoreCat!$F$2:$F$99,0)),50) | AG8: =IFERROR(INDEX(scoreCat!$D$2:$D$99,MATCH("labor|"&E8&"|"&Z8,scoreCat!$F$2:$F$99,0)),50) | AH8: =IFERROR(INDEX(scoreCat!$D$2:$D$99,MATCH("dei|"&F8&"|"&W8,scoreCat!$F$2:$F$99,0)),50) | AI8: =IFERROR(INDEX(scoreCat!$D$2:$D$99,MATCH("animals|"&G8&"|"&X8,scoreCat!$F$2:$F$99,0)),50) | AJ8: =IFERROR(INDEX(scoreCat!$D$2:$D$99,MATCH("guns|"&H8&"|"&Y8,scoreCat!$F$2:$F$99,0)),50) | AK8: =IFERROR(INDEX(scoreCat!$D$2:$D$99,MATCH("privacy|"&I8&"|any",scoreCat!$F$2:$F$99,0)),50) | AL8: =IFERROR(INDEX(scoreCat!$D$2:$D$99,MATCH("execPay|"&J8&"|any",scoreCat!$F$2:$F$99,0)),50) | AM8: =IFERROR(INDEX(scoreCat!$D$2:$D$99,MATCH("health|"&K8&"|any",scoreCat!$F$2:$F$99,0)),50) | AN8: =L8*IF(AND(V8<>"neutral",V8<>""),2,1) | AO8: =M8*1 | AP8: =N8*1 | AQ8: =O8*IF(AND(Z8<>"neutral",Z8<>""),2,1) | AR8: =P8*IF(AND(W8<>"neutral",W8<>""),2,1) | AS8: =Q8*IF(AND(X8<>"neutral",X8<>""),2,1) | AT8: =R8*IF(AND(Y8<>"neutral",Y8<>""),4,1) | AU8: =S8*1 | AV8: =T8*1 | AW8: =U8*1 | AX8: =IF(OR(B8="neutral",B8="na",B8="n/a",B8=""),0,AD8*AN8) | AY8: =IF(OR(C8="neutral",C8="na",C8="n/a",C8=""),0,AE8*AO8) | AZ8: =IF(OR(D8="neutral",D8="na",D8="n/a",D8=""),0,AF8*AP8) | BA8: =IF(OR(E8="neutral",E8="na",E8="n/a",E8=""),0,AG8*AQ8) | BB8: =IF(OR(F8="neutral",F8="na",F8="n/a",F8=""),0,AH8*AR8) | BC8: =IF(OR(G8="neutral",G8="na",G8="n/a",G8=""),0,AI8*AS8) | BD8: =IF(OR(H8="neutral",H8="na",H8="n/a",H8=""),0,AJ8*AT8) | BE8: =IF(OR(I8="neutral",I8="na",I8="n/a",I8=""),0,AK8*AU8) | ... BG8: =IF(OR(K8="neutral",K8="na",K8="n/a",K8=""),0,AM8*AW8) | BH8: =IF(OR(B8="neutral",B8="na",B8="n/a",B8=""),0,AN8)+IF(OR(C8="neutral",C8="na",C8="n/a",C8=""),0,AO8)+IF(OR(D8="neutral",D8="na",D8="n/a",D8=""),0,AP8)+IF(OR(E8="neutral",E8="na",E8="n/a",E8=""),0,AQ8)+IF(OR(F8="neutral",F8="na",F8="n/a",F8=""),0,AR8)+IF(OR(G8="neutral",G8="na",G8="n/a",G8=""),0,AS8)+IF(OR(H8="neutral",H8="na",H8="n/a",H8=""),0,AT8)+IF(OR(I8="neutral",I8="na",I8="n/a",I8=""),0,AU8)+IF(OR(J8="neutral",J8="na",J8="n/a",J8=""),0,AV8)+IF(OR(K8="neutral",K8="na",K8="n/a",K8=""),0,AW8) | BI8: =SUM(AX8:BG8) | BJ8: =IF(BH8=0,"?",BI8/BH8) | BK8: =IF(AA8=TRUE,30,0)+IF(AB8=TRUE,25,0)+IF(AC8=TRUE,30,0) | BL8: =IF(BJ8="?","?",MAX(0,MIN(100,ROUND(BJ8-BK8,0)))) | BM8: =IF(BL8="?","?",IF(BL8>=75,"A",IF(BL8>=62,"B",IF(BL8>=48,"C",IF(BL8>=35,"D","F")))))
A9: (empty row 3) | B9: neutral | C9: neutral | D9: neutral | E9: neutral | F9: neutral | G9: neutral | H9: neutral | I9: neutral | J9: neutral | K9: neutral | L9: 3 | M9: 2 | N9: 3 | O9: 3 | P9: 3 | Q9: 2 | R9: 2 | S9: 2 | T9: 2 | U9: 2 | V9: neutral | W9: neutral | X9: neutral | Y9: neutral | Z9: neutral | AA9: FALSE | AB9: FALSE | AC9: FALSE | AD9: =IFERROR(INDEX(scoreCat!$D$2:$D$99,MATCH("political|"&B9&"|"&V9,scoreCat!$F$2:$F$99,0)),50) | AE9: =IFERROR(INDEX(scoreCat!$D$2:$D$99,MATCH("charity|"&C9&"|any",scoreCat!$F$2:$F$99,0)),50) | AF9: =IFERROR(INDEX(scoreCat!$D$2:$D$99,MATCH("environment|"&D9&"|any",scoreCat!$F$2:$F$99,0)),50) | AG9: =IFERROR(INDEX(scoreCat!$D$2:$D$99,MATCH("labor|"&E9&"|"&Z9,scoreCat!$F$2:$F$99,0)),50) | AH9: =IFERROR(INDEX(scoreCat!$D$2:$D$99,MATCH("dei|"&F9&"|"&W9,scoreCat!$F$2:$F$99,0)),50) | AI9: =IFERROR(INDEX(scoreCat!$D$2:$D$99,MATCH("animals|"&G9&"|"&X9,scoreCat!$F$2:$F$99,0)),50) | AJ9: =IFERROR(INDEX(scoreCat!$D$2:$D$99,MATCH("guns|"&H9&"|"&Y9,scoreCat!$F$2:$F$99,0)),50) | AK9: =IFERROR(INDEX(scoreCat!$D$2:$D$99,MATCH("privacy|"&I9&"|any",scoreCat!$F$2:$F$99,0)),50) | AL9: =IFERROR(INDEX(scoreCat!$D$2:$D$99,MATCH("execPay|"&J9&"|any",scoreCat!$F$2:$F$99,0)),50) | AM9: =IFERROR(INDEX(scoreCat!$D$2:$D$99,MATCH("health|"&K9&"|any",scoreCat!$F$2:$F$99,0)),50) | AN9: =L9*IF(AND(V9<>"neutral",V9<>""),2,1) | AO9: =M9*1 | AP9: =N9*1 | AQ9: =O9*IF(AND(Z9<>"neutral",Z9<>""),2,1) | AR9: =P9*IF(AND(W9<>"neutral",W9<>""),2,1) | AS9: =Q9*IF(AND(X9<>"neutral",X9<>""),2,1) | AT9: =R9*IF(AND(Y9<>"neutral",Y9<>""),4,1) | AU9: =S9*1 | AV9: =T9*1 | AW9: =U9*1 | AX9: =IF(OR(B9="neutral",B9="na",B9="n/a",B9=""),0,AD9*AN9) | AY9: =IF(OR(C9="neutral",C9="na",C9="n/a",C9=""),0,AE9*AO9) | AZ9: =IF(OR(D9="neutral",D9="na",D9="n/a",D9=""),0,AF9*AP9) | BA9: =IF(OR(E9="neutral",E9="na",E9="n/a",E9=""),0,AG9*AQ9) | BB9: =IF(OR(F9="neutral",F9="na",F9="n/a",F9=""),0,AH9*AR9) | BC9: =IF(OR(G9="neutral",G9="na",G9="n/a",G9=""),0,AI9*AS9) | BD9: =IF(OR(H9="neutral",H9="na",H9="n/a",H9=""),0,AJ9*AT9) | BE9: =IF(OR(I9="neutral",I9="na",I9="n/a",I9=""),0,AK9*AU9) | ... BG9: =IF(OR(K9="neutral",K9="na",K9="n/a",K9=""),0,AM9*AW9) | BH9: =IF(OR(B9="neutral",B9="na",B9="n/a",B9=""),0,AN9)+IF(OR(C9="neutral",C9="na",C9="n/a",C9=""),0,AO9)+IF(OR(D9="neutral",D9="na",D9="n/a",D9=""),0,AP9)+IF(OR(E9="neutral",E9="na",E9="n/a",E9=""),0,AQ9)+IF(OR(F9="neutral",F9="na",F9="n/a",F9=""),0,AR9)+IF(OR(G9="neutral",G9="na",G9="n/a",G9=""),0,AS9)+IF(OR(H9="neutral",H9="na",H9="n/a",H9=""),0,AT9)+IF(OR(I9="neutral",I9="na",I9="n/a",I9=""),0,AU9)+IF(OR(J9="neutral",J9="na",J9="n/a",J9=""),0,AV9)+IF(OR(K9="neutral",K9="na",K9="n/a",K9=""),0,AW9) | BI9: =SUM(AX9:BG9) | BJ9: =IF(BH9=0,"?",BI9/BH9) | BK9: =IF(AA9=TRUE,30,0)+IF(AB9=TRUE,25,0)+IF(AC9=TRUE,30,0) | BL9: =IF(BJ9="?","?",MAX(0,MIN(100,ROUND(BJ9-BK9,0)))) | BM9: =IF(BL9="?","?",IF(BL9>=75,"A",IF(BL9>=62,"B",IF(BL9>=48,"C",IF(BL9>=35,"D","F")))))
A10: (empty row 4) | B10: neutral | C10: neutral | D10: neutral | E10: neutral | F10: neutral | G10: neutral | H10: neutral | I10: neutral | J10: neutral | K10: neutral | L10: 3 | M10: 2 | N10: 3 | O10: 3 | P10: 3 | Q10: 2 | R10: 2 | S10: 2 | T10: 2 | U10: 2 | V10: neutral | W10: neutral | X10: neutral | Y10: neutral | Z10: neutral | AA10: FALSE | AB10: FALSE | AC10: FALSE | AD10: =IFERROR(INDEX(scoreCat!$D$2:$D$99,MATCH("political|"&B10&"|"&V10,scoreCat!$F$2:$F$99,0)),50) | AE10: =IFERROR(INDEX(scoreCat!$D$2:$D$99,MATCH("charity|"&C10&"|any",scoreCat!$F$2:$F$99,0)),50) | AF10: =IFERROR(INDEX(scoreCat!$D$2:$D$99,MATCH("environment|"&D10&"|any",scoreCat!$F$2:$F$99,0)),50) | AG10: =IFERROR(INDEX(scoreCat!$D$2:$D$99,MATCH("labor|"&E10&"|"&Z10,scoreCat!$F$2:$F$99,0)),50) | AH10: =IFERROR(INDEX(scoreCat!$D$2:$D$99,MATCH("dei|"&F10&"|"&W10,scoreCat!$F$2:$F$99,0)),50) | AI10: =IFERROR(INDEX(scoreCat!$D$2:$D$99,MATCH("animals|"&G10&"|"&X10,scoreCat!$F$2:$F$99,0)),50) | AJ10: =IFERROR(INDEX(scoreCat!$D$2:$D$99,MATCH("guns|"&H10&"|"&Y10,scoreCat!$F$2:$F$99,0)),50) | AK10: =IFERROR(INDEX(scoreCat!$D$2:$D$99,MATCH("privacy|"&I10&"|any",scoreCat!$F$2:$F$99,0)),50) | AL10: =IFERROR(INDEX(scoreCat!$D$2:$D$99,MATCH("execPay|"&J10&"|any",scoreCat!$F$2:$F$99,0)),50) | AM10: =IFERROR(INDEX(scoreCat!$D$2:$D$99,MATCH("health|"&K10&"|any",scoreCat!$F$2:$F$99,0)),50) | AN10: =L10*IF(AND(V10<>"neutral",V10<>""),2,1) | AO10: =M10*1 | AP10: =N10*1 | AQ10: =O10*IF(AND(Z10<>"neutral",Z10<>""),2,1) | AR10: =P10*IF(AND(W10<>"neutral",W10<>""),2,1) | AS10: =Q10*IF(AND(X10<>"neutral",X10<>""),2,1) | AT10: =R10*IF(AND(Y10<>"neutral",Y10<>""),4,1) | AU10: =S10*1 | AV10: =T10*1 | AW10: =U10*1 | AX10: =IF(OR(B10="neutral",B10="na",B10="n/a",B10=""),0,AD10*AN10) | AY10: =IF(OR(C10="neutral",C10="na",C10="n/a",C10=""),0,AE10*AO10) | AZ10: =IF(OR(D10="neutral",D10="na",D10="n/a",D10=""),0,AF10*AP10) | BA10: =IF(OR(E10="neutral",E10="na",E10="n/a",E10=""),0,AG10*AQ10) | BB10: =IF(OR(F10="neutral",F10="na",F10="n/a",F10=""),0,AH10*AR10) | BC10: =IF(OR(G10="neutral",G10="na",G10="n/a",G10=""),0,AI10*AS10) | BD10: =IF(OR(H10="neutral",H10="na",H10="n/a",H10=""),0,AJ10*AT10) | BE10: =IF(OR(I10="neutral",I10="na",I10="n/a",I10=""),0,AK10*AU10) | ... BG10: =IF(OR(K10="neutral",K10="na",K10="n/a",K10=""),0,AM10*AW10) | BH10: =IF(OR(B10="neutral",B10="na",B10="n/a",B10=""),0,AN10)+IF(OR(C10="neutral",C10="na",C10="n/a",C10=""),0,AO10)+IF(OR(D10="neutral",D10="na",D10="n/a",D10=""),0,AP10)+IF(OR(E10="neutral",E10="na",E10="n/a",E10=""),0,AQ10)+IF(OR(F10="neutral",F10="na",F10="n/a",F10=""),0,AR10)+IF(OR(G10="neutral",G10="na",G10="n/a",G10=""),0,AS10)+IF(OR(H10="neutral",H10="na",H10="n/a",H10=""),0,AT10)+IF(OR(I10="neutral",I10="na",I10="n/a",I10=""),0,AU10)+IF(OR(J10="neutral",J10="na",J10="n/a",J10=""),0,AV10)+IF(OR(K10="neutral",K10="na",K10="n/a",K10=""),0,AW10) | BI10: =SUM(AX10:BG10) | BJ10: =IF(BH10=0,"?",BI10/BH10) | BK10: =IF(AA10=TRUE,30,0)+IF(AB10=TRUE,25,0)+IF(AC10=TRUE,30,0) | BL10: =IF(BJ10="?","?",MAX(0,MIN(100,ROUND(BJ10-BK10,0)))) | BM10: =IF(BL10="?","?",IF(BL10>=75,"A",IF(BL10>=62,"B",IF(BL10>=48,"C",IF(BL10>=35,"D","F")))))
A11: (empty row 5) | B11: neutral | C11: neutral | D11: neutral | E11: neutral | F11: neutral | G11: neutral | H11: neutral | I11: neutral | J11: neutral | K11: neutral | L11: 3 | M11: 2 | N11: 3 | O11: 3 | P11: 3 | Q11: 2 | R11: 2 | S11: 2 | T11: 2 | U11: 2 | V11: neutral | W11: neutral | X11: neutral | Y11: neutral | Z11: neutral | AA11: FALSE | AB11: FALSE | AC11: FALSE | AD11: =IFERROR(INDEX(scoreCat!$D$2:$D$99,MATCH("political|"&B11&"|"&V11,scoreCat!$F$2:$F$99,0)),50) | AE11: =IFERROR(INDEX(scoreCat!$D$2:$D$99,MATCH("charity|"&C11&"|any",scoreCat!$F$2:$F$99,0)),50) | AF11: =IFERROR(INDEX(scoreCat!$D$2:$D$99,MATCH("environment|"&D11&"|any",scoreCat!$F$2:$F$99,0)),50) | AG11: =IFERROR(INDEX(scoreCat!$D$2:$D$99,MATCH("labor|"&E11&"|"&Z11,scoreCat!$F$2:$F$99,0)),50) | AH11: =IFERROR(INDEX(scoreCat!$D$2:$D$99,MATCH("dei|"&F11&"|"&W11,scoreCat!$F$2:$F$99,0)),50) | AI11: =IFERROR(INDEX(scoreCat!$D$2:$D$99,MATCH("animals|"&G11&"|"&X11,scoreCat!$F$2:$F$99,0)),50) | AJ11: =IFERROR(INDEX(scoreCat!$D$2:$D$99,MATCH("guns|"&H11&"|"&Y11,scoreCat!$F$2:$F$99,0)),50) | AK11: =IFERROR(INDEX(scoreCat!$D$2:$D$99,MATCH("privacy|"&I11&"|any",scoreCat!$F$2:$F$99,0)),50) | AL11: =IFERROR(INDEX(scoreCat!$D$2:$D$99,MATCH("execPay|"&J11&"|any",scoreCat!$F$2:$F$99,0)),50) | AM11: =IFERROR(INDEX(scoreCat!$D$2:$D$99,MATCH("health|"&K11&"|any",scoreCat!$F$2:$F$99,0)),50) | AN11: =L11*IF(AND(V11<>"neutral",V11<>""),2,1) | AO11: =M11*1 | AP11: =N11*1 | AQ11: =O11*IF(AND(Z11<>"neutral",Z11<>""),2,1) | AR11: =P11*IF(AND(W11<>"neutral",W11<>""),2,1) | AS11: =Q11*IF(AND(X11<>"neutral",X11<>""),2,1) | AT11: =R11*IF(AND(Y11<>"neutral",Y11<>""),4,1) | AU11: =S11*1 | AV11: =T11*1 | AW11: =U11*1 | AX11: =IF(OR(B11="neutral",B11="na",B11="n/a",B11=""),0,AD11*AN11) | AY11: =IF(OR(C11="neutral",C11="na",C11="n/a",C11=""),0,AE11*AO11) | AZ11: =IF(OR(D11="neutral",D11="na",D11="n/a",D11=""),0,AF11*AP11) | BA11: =IF(OR(E11="neutral",E11="na",E11="n/a",E11=""),0,AG11*AQ11) | BB11: =IF(OR(F11="neutral",F11="na",F11="n/a",F11=""),0,AH11*AR11) | BC11: =IF(OR(G11="neutral",G11="na",G11="n/a",G11=""),0,AI11*AS11) | BD11: =IF(OR(H11="neutral",H11="na",H11="n/a",H11=""),0,AJ11*AT11) | BE11: =IF(OR(I11="neutral",I11="na",I11="n/a",I11=""),0,AK11*AU11) | ... BG11: =IF(OR(K11="neutral",K11="na",K11="n/a",K11=""),0,AM11*AW11) | BH11: =IF(OR(B11="neutral",B11="na",B11="n/a",B11=""),0,AN11)+IF(OR(C11="neutral",C11="na",C11="n/a",C11=""),0,AO11)+IF(OR(D11="neutral",D11="na",D11="n/a",D11=""),0,AP11)+IF(OR(E11="neutral",E11="na",E11="n/a",E11=""),0,AQ11)+IF(OR(F11="neutral",F11="na",F11="n/a",F11=""),0,AR11)+IF(OR(G11="neutral",G11="na",G11="n/a",G11=""),0,AS11)+IF(OR(H11="neutral",H11="na",H11="n/a",H11=""),0,AT11)+IF(OR(I11="neutral",I11="na",I11="n/a",I11=""),0,AU11)+IF(OR(J11="neutral",J11="na",J11="n/a",J11=""),0,AV11)+IF(OR(K11="neutral",K11="na",K11="n/a",K11=""),0,AW11) | BI11: =SUM(AX11:BG11) | BJ11: =IF(BH11=0,"?",BI11/BH11) | BK11: =IF(AA11=TRUE,30,0)+IF(AB11=TRUE,25,0)+IF(AC11=TRUE,30,0) | BL11: =IF(BJ11="?","?",MAX(0,MIN(100,ROUND(BJ11-BK11,0)))) | BM11: =IF(BL11="?","?",IF(BL11>=75,"A",IF(BL11>=62,"B",IF(BL11>=48,"C",IF(BL11>=35,"D","F")))))
A13: HOW TO USE: Edit any YELLOW cell in rows 3–11. The light-blue 'Result' columns recompute automatically. Reference scoreCat / Weights / Dealbreakers sheets for the lookup tables.

Sheet scoreCat
A1: Category | B1: Enum value | C1: User stance | D1: Score | E1: Notes | F1: key
A2: political | B2: left | C2: left | D2: 97 | E2: User picked Democrat, company donates left → strong positive | F2: =A2&"|"&B2&"|"&C2
A3: political | B3: left-leaning | C3: left | D3: 97 | E3: Same as left | F3: =A3&"|"&B3&"|"&C3
A4: political | B4: bipartisan | C4: left | D4: 62 | E4: Neutral company, slight positive for D user | F4: =A4&"|"&B4&"|"&C4
A5: political | B5: mixed | C5: left | D5: 62 | E5: Same | F5: =A5&"|"&B5&"|"&C5
A6: political | B6: neutral | C6: left | D6: 48 | E6: No data | F6: =A6&"|"&B6&"|"&C6
A7: political | B7: right | C7: left | D7: 8 | E7: Opposite stance — heavy penalty | F7: =A7&"|"&B7&"|"&C7
A8: political | B8: right-leaning | C8: left | D8: 8 | E8: Same | F8: =A8&"|"&B8&"|"&C8
A9: political | B9: left | C9: right | D9: 8 | E9: Opposite stance for R user | F9: =A9&"|"&B9&"|"&C9
A10: political | B10: left-leaning | C10: right | D10: 8 | E10: Same | F10: =A10&"|"&B10&"|"&C10
A11: political | B11: bipartisan | C11: right | D11: 62 | E11: Slight positive | F11: =A11&"|"&B11&"|"&C11
A12: political | B12: mixed | C12: right | D12: 62 | F12: =A12&"|"&B12&"|"&C12
A13: political | B13: neutral | C13: right | D13: 48 | F13: =A13&"|"&B13&"|"&C13
A14: political | B14: right | C14: right | D14: 97 | E14: Match — strong positive | F14: =A14&"|"&B14&"|"&C14
A15: political | B15: right-leaning | C15: right | D15: 97 | F15: =A15&"|"&B15&"|"&C15
A16: political | B16: bipartisan | C16: neutral | D16: 80 | E16: No user lean, bipartisan = good | F16: =A16&"|"&B16&"|"&C16
A17: political | B17: mixed | C17: neutral | D17: 80 | F17: =A17&"|"&B17&"|"&C17
A18: political | B18: neutral | C18: neutral | D18: 72 | F18: =A18&"|"&B18&"|"&C18
A19: political | B19: left | C19: neutral | D19: 52 | F19: =A19&"|"&B19&"|"&C19
A20: political | B20: right | C20: neutral | D20: 52 | F20: =A20&"|"&B20&"|"&C20
A21: political | B21: left-leaning | C21: neutral | D21: 52 | F21: =A21&"|"&B21&"|"&C21
A22: political | B22: right-leaning | C22: neutral | D22: 52 | F22: =A22&"|"&B22&"|"&C22
A23: dei | B23: pro_dei | C23: pro | D23: 97 | E23: Pro-DEI user, company has DEI programs | F23: =A23&"|"&B23&"|"&C23
A24: dei | B24: mixed | C24: pro | D24: 52 | F24: =A24&"|"&B24&"|"&C24
A25: dei | B25: neutral | C25: pro | D25: 45 | F25: =A25&"|"&B25&"|"&C25
A26: dei | B26: anti_dei | C26: pro | D26: 5 | E26: Opposite stance — heavy penalty | F26: =A26&"|"&B26&"|"&C26
A27: dei | B27: anti_dei | C27: anti | D27: 97 | E27: Anti-DEI user, company anti-DEI | F27: =A27&"|"&B27&"|"&C27
A28: dei | B28: mixed | C28: anti | D28: 52 | F28: =A28&"|"&B28&"|"&C28
A29: dei | B29: neutral | C29: anti | D29: 45 | F29: =A29&"|"&B29&"|"&C29
A30: dei | B30: pro_dei | C30: anti | D30: 5 | E30: Opposite stance | F30: =A30&"|"&B30&"|"&C30
A31: dei | B31: pro_dei | C31: neutral | D31: 62 | E31: No user preference | F31: =A31&"|"&B31&"|"&C31
A32: dei | B32: anti_dei | C32: neutral | D32: 62 | F32: =A32&"|"&B32&"|"&C32
A33: dei | B33: mixed | C33: neutral | D33: 62 | F33: =A33&"|"&B33&"|"&C33
A34: animals | B34: cruelty_free | C34: dealbreaker | D34: 97 | E34: User picks animal testing as dealbreaker | F34: =A34&"|"&B34&"|"&C34
A35: animals | B35: some_testing | C35: dealbreaker | D35: 15 | F35: =A35&"|"&B35&"|"&C35
A36: animals | B36: tests_animals | C36: dealbreaker | D36: 0 | E36: Triggers animal-testing dealbreaker — see Dealbreakers sheet | F36: =A36&"|"&B36&"|"&C36
A37: animals | B37: cruelty_free | C37: prefer_not | D37: 92 | E37: User prefers not | F37: =A37&"|"&B37&"|"&C37
A38: animals | B38: some_testing | C38: prefer_not | D38: 52 | F38: =A38&"|"&B38&"|"&C38
A39: animals | B39: tests_animals | C39: prefer_not | D39: 20 | F39: =A39&"|"&B39&"|"&C39
A40: animals | B40: cruelty_free | C40: neutral | D40: 62 | F40: =A40&"|"&B40&"|"&C40
...

Sheet Weights
A1: Category | B1: Default weight | C1: Boost trigger | D1: Boost multiplier | E1: Notes | G1: Category | H1: Boost field | I1: Max boost
A2: political | B2: 3 | C2: lean ≠ neutral | D2: 2 | E2: Active political opinion doubles weight | G2: political | H2: lean | I2: 2
A3: charity | B3: 2 | C3: (no boost) | D3: 1 | G3: charity | I3: 1
A4: environment | B4: 3 | C4: (no boost) | D4: 1 | G4: environment | I4: 1
A5: labor | B5: 3 | C5: unionSupport ≠ neutral | D5: 2 | E5: Pro- or anti-union user doubles labor weight | G5: labor | H5: unionSupport | I5: 2
A6: dei | B6: 3 | C6: deiLean ≠ neutral | D6: 2 | E6: Active DEI stance doubles weight | G6: dei | H6: deiLean | I6: 2
A7: animals | B7: 2 | C7: animalTesting ≠ neutral | D7: 2 | E7: Active animal stance doubles weight | G7: animals | H7: animalTesting | I7: 2
A8: guns | B8: 2 | C8: guns ≠ neutral | D8: 4 | E8: Active gun stance QUADRUPLES weight (strong-opinion category) | G8: guns | H8: guns | I8: 4
A9: privacy | B9: 2 | C9: (no boost) | D9: 1 | G9: privacy | I9: 1
A10: execPay | B10: 2 | C10: (no boost) | D10: 1 | G10: execPay | I10: 1
A11: health | B11: 2 | C11: (no boost) | D11: 1 | E11: Health category not in default profile.weights | G11: health | I11: 1

Sheet Dealbreakers
A1: Dealbreaker key | B1: Triggers when | C1: Penalty (points) | D1: Notes
A2: foreignOwn | B2: company.foreignOwned == true | C2: -30 | D2: Was Nestlé's case (UK HQ)
A3: childLabor | B3: company.childLabor == true | C3: -30
A4: monopoly | B4: company.antitrust == true | C4: -25
A5: forcedLabor | B5: sc.labor == 'poor' | C5: -25
A6: darkPatterns | B6: sc.privacy == 'poor' | C6: -20
A7: taxAvoidance | B7: sc.execPay == 'poor' | C7: -15
A8: predatoryPrice | B8: sc.labor == 'poor' | C8: -15
A9: environment | B9: sc.environment in [negative/poor/very poor/below avg] | C9: -20 | D9: Standard category dealbreaker
A10: labor | B10: sc.labor in [negative/poor/very poor/below avg] | C10: -20
A11: privacy | B11: sc.privacy in [poor] | C11: -20
A12: execPay | B12: sc.execPay in [poor] | C12: -20
A13: animals | B13: sc.animals in [tests_animals] | C13: -20 | D13: Standard category dealbreaker
A14: guns | B14: sc.guns in [sells_guns / makes_guns] | C14: -20
A15: charity | B15: sc.charity in [negative/poor] | C15: -20
A16: animalTesting (special) | B16: profile.animalTesting == 'dealbreaker' AND sc.animals == 'tests_animals' | C16: -40 | D16: SPECIAL: returns max(0, min(ws-40, 30)) — caps score at 30

Sheet Grade Thresholds
A1: Letter | B1: Score range | C1: Notes | E1: Min score | F1: Letter
A2: A | B2: ≥ 75 | C2: Truly exceptional (only ~0.04% of brands post Build 54) | E2: 0 | F2: F
A3: B | B3: ≥ 62 | C3: Very good | E3: 35 | F3: D
A4: C | B4: ≥ 48 | C4: Average / middle of pack | E4: 48 | F4: C
A5: D | B5: ≥ 35 | C5: Below average | E5: 62 | F5: B
A6: F | B6: < 35 | C6: Significant negative signals | E6: 75 | F6: A
A7: ? | B7: null | C7: Insufficient data — 0 contributing categories
